Workbook

Sheet 总览Dashboard
A1: 宇宙藏书阁 · 统计总览
A4: 书籍总数 | E4: 中文篇数 | H4: 英文篇数
A6: =MAX(中文书目!A2:A1000) -> 368 | E6: =MAX(中文书目!A2:A1000) -> 368 | H6: =COUNTA([1]作品总表!D2:D400) -> 0
A11: 未开始 | D11: 下载中 | G11: 完结 | J11: 完结（保密）
A13: =COUNTIF(中文书目!K2:K1000,"未开始") -> 34 | D13: =COUNTIF(中文书目!K2:K1000,"下载中") -> 36 | G13: =COUNTIF(中文书目!K2:K1000,"完结") -> 239 | J13: =COUNTIF(中文书目!K2:K1000,"完结保密") -> 1
A17: 目标用户：小白用户 | C17: 目标用户：正式学员 | E17: 西方 | G17: 阿拉伯
A19: =COUNTIF(中文书目!F$2:F$1000,"公共") -> 85 | C19: =A6-A19-E19-G19 -> 268 | E19: =COUNTIF(中文书目!F$2:F$1000,"西方") -> 12 | G19: =COUNTIF(中文书目!F$2:F$1000,"阿拉伯") -> 3
A23: 在《作品总表》中粘贴数据：书名-中文、书名-英文、状态、目标用户等。本页自动统计。

Sheet 中文书目
A1: 序号 | B1: 类别标签 | C1: 首篇时间 | D1: 首篇时间 | E1: 书名 | F1: 阶别 | G1: 管道 | H1: 总章节数 | I1: 下载数 | J1: 翻译版本 | K1: 下载状态 | L1: 发表 | M1: 配音音频 | N1: 配音 | O1: 是否全部发表 | P1: 版权类别 | Q1: 存证日期 | R1: 版权登记日期 | S1: 版权状态 | V1: 管道 | W1: 阶别 | X1: 类别标签 | Y1: 关键词 | AA1: 类别 | AB1: 存证日期 | AC1: 版权登记日期 | AD1: 状态 | AE1: 类别 | AF1: 存证日期 | AG1: 版权登记日期 | AH1: 状态 | AK1: 旧标签
A2: 1 | B2: 08-灵性成长-灵性基础 | C2: =YEAR(D2) -> 2019 | D2: 43466 | E2: 一个灵魂飞到宇宙中的女人 | F2: 一阶 | G2: 星姐 | H2: 2 | I2: 2 | K2: =IF(H2=I2,"完结",IF(H2>I2,"未完结")) -> 完结 | L2: 2 | O2: =IF(H2=L2,"完",IF(H2>L2,"未")) -> 完 | Z2: 意识与能量 | AA2: 省版 | AB2: 2025/6/6 | AC2: 2025/7/4 | AD2: 已发证 | AE2: =VLOOKUP($E2,$Z$2:$AD$76,2,FALSE) -> #N/A | AF2: =VLOOKUP($E2,$Z$2:$AD$76,3,FALSE) -> #N/A | AG2: =VLOOKUP($E2,$Z$2:$AD$76,4,FALSE) -> #N/A | AH2: =VLOOKUP($E2,$Z$2:$AD$76,5,FALSE) -> #N/A | AK2: 08-灵性成长
A3: 2 | B3: 07-经典经文 | C3: =YEAR(D3) -> 2019 | D3: 43739 | E3: 经典新解 | F3: 一阶 | G3: 星姐 | H3: 5 | I3: 5 | K3: =IF(H3=I3,"完结",IF(H3>I3,"未完结")) -> 完结 | L3: 0 | O3: =IF(H3=L3,"完",IF(H3>L3,"未")) -> 未 | V3: 沛生 | W3: 公共 | X3: 01-宇宙知识-宇宙法则 | Y3: 能量，意识，空间构造，起源 | Z3: 人类意识走向 | AA3: 省版 | AB3: 2025/6/6 | AC3: 2025/7/4 | AD3: 已发证 | AE3: =VLOOKUP($E3,$Z$2:$AD$76,2,FALSE) -> #N/A | AF3: =VLOOKUP($E3,$Z$2:$AD$76,3,FALSE) -> #N/A | AG3: =VLOOKUP($E3,$Z$2:$AD$76,4,FALSE) -> #N/A | AH3: =VLOOKUP($E3,$Z$2:$AD$76,5,FALSE) -> #N/A | AK3: 03-佛法知识-经典
A4: 3 | B4: 08-灵性成长-灵性基础 | C4: =YEAR(D4) -> 2019 | D4: 43775 | E4: 宇宙之声 | F4: 二阶 | G4: 李静 | H4: 19 | I4: 19 | K4: =IF(H4=I4,"完结",IF(H4>I4,"未完结")) -> 完结 | L4: 19 | O4: =IF(H4=L4,"完",IF(H4>L4,"未")) -> 完 | P4: 省版 | Q4: 2025/6/4 | R4: 2025/7/4 | S4: 已发证 | V4: 孟昭宇 | W4: 一阶 | X4: 02-宇宙知识-平行空间 | Y4: 各次元空间文明 | Z4: 生物意识起源之地球篇 | AA4: 省版 | AB4: 2025/6/6 | AC4: 2025/7/4 | AD4: 已发证 | AE4: =VLOOKUP($E4,$Z$2:$AD$76,2,FALSE) -> 省版 | AF4: =VLOOKUP($E4,$Z$2:$AD$76,3,FALSE) -> 2025/6/4 | AG4: =VLOOKUP($E4,$Z$2:$AD$76,4,FALSE) -> 2025/7/4 | AH4: =VLOOKUP($E4,$Z$2:$AD$76,5,FALSE) -> 已发证 | AK4: 08-灵性成长
A5: 4 | B5: 11-修行修心-修心基础 | C5: =YEAR(D5) -> 2019 | D5: 43796 | E5: 宝生佛的自然课堂 | F5: 一阶 | G5: 沛生 | H5: 27 | I5: 27 | K5: =IF(H5=I5,"完结",IF(H5>I5,"未完结")) -> 完结 | L5: 27 | O5: =IF(H5=L5,"完",IF(H5>L5,"未")) -> 完 | V5: 王靖 | W5: 一阶 | X5: 03-宇宙知识-外星文明 | Y5: 外星世界文明、科技 | Z5: 极致大脑 | AA5: 省版 | AB5: 2025/6/5 | AE5: =VLOOKUP($E5,$Z$2:$AD$76,2,FALSE) -> #N/A | AF5: =VLOOKUP($E5,$Z$2:$AD$76,3,FALSE) -> #N/A | AG5: =VLOOKUP($E5,$Z$2:$AD$76,4,FALSE) -> #N/A | AH5: =VLOOKUP($E5,$Z$2:$AD$76,5,FALSE) -> #N/A | AK5: 08-灵性成长
A6: 5 | B6: 03-宇宙知识-外星文明 | C6: =YEAR(D6) -> 2019 | D6: 43800 | E6: 外星高科技 | F6: 一阶 | G6: 吴英 | H6: 5 | I6: 5 | K6: =IF(H6=I6,"完结",IF(H6>I6,"未完结")) -> 完结 | L6: 5 | O6: =IF(H6=L6,"完",IF(H6>L6,"未")) -> 完 | P6: 0 | Q6: 2025/5/30 | R6: 0 | S6: 阶段稿已存证 | V6: 惠敏 | W6: 二阶 | X6: 04-地球文明/地球扬升 | Y6: 地球扬升，高维地球，地球文明史 | Z6: 减压脑科学 | AA6: 省版 | AB6: 2025/6/5 | AE6: =VLOOKUP($E6,$Z$2:$AD$76,2,FALSE) -> 0 | AF6: =VLOOKUP($E6,$Z$2:$AD$76,3,FALSE) -> 2025/5/30 | AG6: =VLOOKUP($E6,$Z$2:$AD$76,4,FALSE) -> 0 | AH6: =VLOOKUP($E6,$Z$2:$AD$76,5,FALSE) -> 阶段稿已存证 | AK6: 07-宇宙知识-宇宙文明
A7: 6 | B7: 12-修行修心-实修指南 | C7: =YEAR(D7) -> 2019 | D7: 43808 | E7: 心法 | F7: 一阶 | G7: 昱嘉 | H7: 19 | I7: 19 | K7: =IF(H7=I7,"完结",IF(H7>I7,"未完结")) -> 完结 | L7: 18 | O7: =IF(H7=L7,"完",IF(H7>L7,"未")) -> 未 | V7: 蒋迎迎 | W7: 三阶 | X7: 05-宇宙科学/现代科技 | Y7: 量子理论，人工智能等（偏运用） | Z7: 造物意识 | AA7: 省版 | AB7: 2025/6/5 | AE7: =VLOOKUP($E7,$Z$2:$AD$76,2,FALSE) -> #N/A | AF7: =VLOOKUP($E7,$Z$2:$AD$76,3,FALSE) -> #N/A | AG7: =VLOOKUP($E7,$Z$2:$AD$76,4,FALSE) -> #N/A | AH7: =VLOOKUP($E7,$Z$2:$AD$76,5,FALSE) -> #N/A | AK7: 03-佛法知识-经典
A8: 7 | B8: 04-地球文明/地球扬升 | C8: =YEAR(D8) -> 2019 | D8: 43808 | E8: 地球提升之路 | F8: 一阶 | G8: 杜旻旻 | H8: 8 | I8: 8 | K8: =IF(H8=I8,"完结",IF(H8>I8,"未完结")) -> 完结 | L8: 7 | O8: =IF(H8=L8,"完",IF(H8>L8,"未")) -> 未 | P8: 省版 | Q8: 2025/5/30 | R8: 2025/7/3 | S8: 已发证 | V8: 刘小慧 | W8: 四阶 | X8: 06-佛法基础常识 | Y8: 佛法理论 | Z8: 源头与意识 | AA8: 省版 | AB8: 2025/6/5 | AE8: =VLOOKUP($E8,$Z$2:$AD$76,2,FALSE) -> 省版 | AF8: =VLOOKUP($E8,$Z$2:$AD$76,3,FALSE) -> 2025/5/30 | AG8: =VLOOKUP($E8,$Z$2:$AD$76,4,FALSE) -> 2025/7/3 | AH8: =VLOOKUP($E8,$Z$2:$AD$76,5,FALSE) -> 已发证 | AK8: 04-地球扬升
A9: 8 | B9: 17-高维文学-散文诗 | C9: =YEAR(D9) -> 2019 | D9: 43827 | E9: 梅集 | F9: 一阶 | G9: 共同参与 | H9: 145 | I9: 145 | K9: =IF(H9=I9,"完结",IF(H9>I9,"未完结")) -> 完结 | L9: 0 | O9: =IF(H9=L9,"完",IF(H9>L9,"未")) -> 未 | V9: 李静 | W9: 课程专用 | X9: 07-经典经文 | Y9: 经典 | Z9: 上帝粒子 | AA9: 省版 | AB9: 2025/6/5 | AE9: =VLOOKUP($E9,$Z$2:$AD$76,2,FALSE) -> #N/A | AF9: =VLOOKUP($E9,$Z$2:$AD$76,3,FALSE) -> #N/A | AG9: =VLOOKUP($E9,$Z$2:$AD$76,4,FALSE) -> #N/A | AH9: =VLOOKUP($E9,$Z$2:$AD$76,5,FALSE) -> #N/A | AK9: 16-诗
A10: 9 | B10: 08-灵性成长-灵性基础 | C10: =YEAR(D10) -> 2019 | D10: 43828 | E10: 人体与灵魂的未解之谜 | F10: 一阶 | G10: 李静 | H10: 16 | I10: 16 | K10: =IF(H10=I10,"完结",IF(H10>I10,"未完结")) -> 完结 | L10: 16 | O10: =IF(H10=L10,"完",IF(H10>L10,"未")) -> 完 | P10: 省版 | Q10: 2025/6/4 | R10: 0 | S10: 0 | V10: 张轶群 | W10: 西方 | X10: 08-灵性成长-灵性基础 | Y10: 灵性基础、散文类、灵性知识类、揭秘类、理论 | Z10: 生命科学与空性智慧 | AA10: 省版 | AB10: 2025/6/5 | AE10: =VLOOKUP($E10,$Z$2:$AD$76,2,FALSE) -> 省版 | AF10: =VLOOKUP($E10,$Z$2:$AD$76,3,FALSE) -> 2025/6/4 | AG10: =VLOOKUP($E10,$Z$2:$AD$76,4,FALSE) -> 0 | AH10: =VLOOKUP($E10,$Z$2:$AD$76,5,FALSE) -> 0 | AK10: 08-灵性成长
A11: 10 | B11: 18-高维文学-小说 | C11: =YEAR(D11) -> 2020 | D11: 43831 | E11: 来自地心的问候 | F11: - | G11: 昱嘉 | H11: 19 | I11: 19 | K11: 无文稿 | L11: 0 | O11: =IF(H11=L11,"完",IF(H11>L11,"未")) -> 未 | V11: 刘冬梅 | W11: 阿拉伯 | X11: 10-灵性成长-身心疗愈 | Y11: 能量疗愈，情绪管理 | Z11: 宇宙科学能量疗法 | AA11: 省版 | AB11: 2025/6/5 | AE11: =VLOOKUP($E11,$Z$2:$AD$76,2,FALSE) -> #N/A | AF11: =VLOOKUP($E11,$Z$2:$AD$76,3,FALSE) -> #N/A | AG11: =VLOOKUP($E11,$Z$2:$AD$76,4,FALSE) -> #N/A | AH11: =VLOOKUP($E11,$Z$2:$AD$76,5,FALSE) -> #N/A | AK11: 13-小说
A12: 11 | B12: 18-高维文学-小说 | C12: =YEAR(D12) -> 2020 | D12: 43860 | E12: 我眼中的宇宙之王 | F12: - | G12: 昱嘉 | H12: 16 | I12: 16 | K12: 无文稿 | L12: 0 | O12: =IF(H12=L12,"完",IF(H12>L12,"未")) -> 未 | V12: 陈琪琪 | X12: 11-修行修心-修心基础 | Y12: 修心知识、散文 | Z12: 能量疗愈显相法 | AA12: 省版 | AB12: 2025/6/5 | AE12: =VLOOKUP($E12,$Z$2:$AD$76,2,FALSE) -> #N/A | AF12: =VLOOKUP($E12,$Z$2:$AD$76,3,FALSE) -> #N/A | AG12: =VLOOKUP($E12,$Z$2:$AD$76,4,FALSE) -> #N/A | AH12: =VLOOKUP($E12,$Z$2:$AD$76,5,FALSE) -> #N/A | AK12: 13-小说
A13: 12 | B13: 08-灵性成长-灵性基础 | C13: =YEAR(D13) -> 2020 | D13: 43861 | E13: 明日之歌 | F13: 一阶 | G13: 刘小慧 | H13: 19 | I13: 19 | K13: =IF(H13=I13,"完结",IF(H13>I13,"未完结")) -> 完结 | L13: 19 | O13: =IF(H13=L13,"完",IF(H13>L13,"未")) -> 完 | V13: 林巧玲 | X13: 12-修行修心-实修指南 | Y13: 禅修，冥想方法，灵魂觉醒 | Z13: 能量法则 | AA13: 省版 | AB13: 2025/6/5 | AE13: =VLOOKUP($E13,$Z$2:$AD$76,2,FALSE) -> #N/A | AF13: =VLOOKUP($E13,$Z$2:$AD$76,3,FALSE) -> #N/A | AG13: =VLOOKUP($E13,$Z$2:$AD$76,4,FALSE) -> #N/A | AH13: =VLOOKUP($E13,$Z$2:$AD$76,5,FALSE) -> #N/A | AK13: 08-灵性成长
A14: 13 | B14: 07-经典经文 | C14: =YEAR(D14) -> 2020 | D14: 43862 | E14: 礼记 | F14: 二阶 | G14: 刘冬梅 | H14: 8 | I14: 8 | K14: =IF(H14=I14,"完结",IF(H14>I14,"未完结")) -> 完结 | L14: 8 | O14: =IF(H14=L14,"完",IF(H14>L14,"未")) -> 完 | V14: 周统志 | X14: 13-落地智慧-日常生活 | Y14: 衣食住行，个人提升 | Z14: 空性能量 | AA14: 省版 | AB14: 2025/6/5 | AE14: =VLOOKUP($E14,$Z$2:$AD$76,2,FALSE) -> #N/A | AF14: =VLOOKUP($E14,$Z$2:$AD$76,3,FALSE) -> #N/A | AG14: =VLOOKUP($E14,$Z$2:$AD$76,4,FALSE) -> #N/A | AH14: =VLOOKUP($E14,$Z$2:$AD$76,5,FALSE) -> #N/A | AK14: 03-佛法知识-经典
A15: 14 | B15: 18-高维文学-小说 | C15: =YEAR(D15) -> 2020 | D15: 43862 | E15: 公约社区 | F15: 二阶 | G15: 海榆 | H15: ？ | I15: 19 | K15: =IF(H15=I15,"完结",IF(H15>I15,"下载中")) -> 下载中 | L15: 15 | O15: =IF(H15=L15,"完",IF(H15>L15,"未")) -> 未 | V15: 昱嘉 | X15: 14-落地智慧-事业财富 | Y15: 事业，财富 | Z15: 金钱能量 | AA15: 省版 | AB15: 2025/6/5 | AE15: =VLOOKUP($E15,$Z$2:$AD$76,2,FALSE) -> #N/A | AF15: =VLOOKUP($E15,$Z$2:$AD$76,3,FALSE) -> #N/A | AG15: =VLOOKUP($E15,$Z$2:$AD$76,4,FALSE) -> #N/A | AH15: =VLOOKUP($E15,$Z$2:$AD$76,5,FALSE) -> #N/A | AK15: 13-小说
A16: 15 | B16: 18-高维文学-小说 | C16: =YEAR(D16) -> 2020 | D16: 43864 | E16: 无限 | F16: - | G16: 昱嘉 | H16: 4 | I16: 4 | K16: 无文稿 | L16: 0 | O16: =IF(H16=L16,"完",IF(H16>L16,"未")) -> 未 | V16: 温愉琦 | X16: 15-落地智慧-人际关系 | Y16: 爱情，亲子，朋友等 | Z16: 植物能量的起源 | AA16: 省版 | AB16: 2025/6/5 | AE16: =VLOOKUP($E16,$Z$2:$AD$76,2,FALSE) -> #N/A | AF16: =VLOOKUP($E16,$Z$2:$AD$76,3,FALSE) -> #N/A | AG16: =VLOOKUP($E16,$Z$2:$AD$76,4,FALSE) -> #N/A | AH16: =VLOOKUP($E16,$Z$2:$AD$76,5,FALSE) -> #N/A | AK16: 13-小说
A17: 16 | B17: 20-高维解读-时事点评 | C17: =YEAR(D17) -> 2020 | D17: 43864 | E17: 疫情报告 | F17: - | G17: 昱嘉 | H17: 1 | I17: 1 | K17: 暂停 | L17: 0 | O17: =IF(H17=L17,"完",IF(H17>L17,"未")) -> 未 | V17: 共同参与 | X17: 16-新文明新商业 | Z17: 宇宙能量与灵魂的关系 | AA17: 省版 | AB17: 2025/6/5 | AE17: =VLOOKUP($E17,$Z$2:$AD$76,2,FALSE) -> #N/A | AF17: =VLOOKUP($E17,$Z$2:$AD$76,3,FALSE) -> #N/A | AG17: =VLOOKUP($E17,$Z$2:$AD$76,4,FALSE) -> #N/A | AH17: =VLOOKUP($E17,$Z$2:$AD$76,5,FALSE) -> #N/A | AK17: 99-暂停
A18: 17 | B18: 08-灵性成长-灵性基础 | C18: =YEAR(D18) -> 2020 | D18: 43869 | E18: 灵性文章合集（中英文） | F18: 一阶 | G18: 徐丹 | H18: 27 | I18: 27 | K18: =IF(H18=I18,"完结",IF(H18>I18,"未完结")) -> 完结 | L18: 27 | O18: =IF(H18=L18,"完",IF(H18>L18,"未")) -> 完 | V18: 徐丹 | X18: 17-高维文学-散文诗 | Z18: 链接灵魂 | AA18: 省版 | AB18: 2025/6/5 | AE18: =VLOOKUP($E18,$Z$2:$AD$76,2,FALSE) -> #N/A | AF18: =VLOOKUP($E18,$Z$2:$AD$76,3,FALSE) -> #N/A | AG18: =VLOOKUP($E18,$Z$2:$AD$76,4,FALSE) -> #N/A | AH18: =VLOOKUP($E18,$Z$2:$AD$76,5,FALSE) -> #N/A | AK18: 08-灵性成长
A19: 18 | B19: 18-高维文学-小说 | C19: =YEAR(D19) -> 2020 | D19: 43882 | E19: 森林之子 | F19: 公共 | G19: 刘小慧 | H19: 10 | I19: 10 | K19: =IF(H19=I19,"完结",IF(H19>I19,"未完结")) -> 完结 | L19: 10 | O19: =IF(H19=L19,"完",IF(H19>L19,"未")) -> 完 | V19: 含灵 | X19: 18-高维文学-小说 | Z19: 灵魂觉醒 | AA19: 省版 | AB19: 2025/6/5 | AE19: =VLOOKUP($E19,$Z$2:$AD$76,2,FALSE) -> #N/A | AF19: =VLOOKUP($E19,$Z$2:$AD$76,3,FALSE) -> #N/A | AG19: =VLOOKUP($E19,$Z$2:$AD$76,4,FALSE) -> #N/A | AH19: =VLOOKUP($E19,$Z$2:$AD$76,5,FALSE) -> #N/A | AK19: 13-小说
A20: 19 | B20: 08-灵性成长-灵性基础 | C20: =YEAR(D20) -> 2020 | D20: 43883 | E20: 生命之花 | F20: 一阶 | G20: 刘小慧 | H20: 10 | I20: 10 | K20: =IF(H20=I20,"完结",IF(H20>I20,"未完结")) -> 完结 | L20: 10 | O20: =IF(H20=L20,"完",IF(H20>L20,"未")) -> 完 | V20: 星姐 | X20: 19-人物揭秘/传记 | Z20: 解密灵魂出窍 | AA20: 省版 | AB20: 2025/6/5 | AE20: =VLOOKUP($E20,$Z$2:$AD$76,2,FALSE) -> #N/A | AF20: =VLOOKUP($E20,$Z$2:$AD$76,3,FALSE) -> #N/A | AG20: =VLOOKUP($E20,$Z$2:$AD$76,4,FALSE) -> #N/A | AH20: =VLOOKUP($E20,$Z$2:$AD$76,5,FALSE) -> #N/A | AK20: 08-灵性成长
A21: 20 | B21: 07-经典经文 | C21: =YEAR(D21) -> 2020 | D21: 43885 | E21: 四书五经 | F21: 二阶 | G21: 刘冬梅 | H21: =12+8+5+2+8 -> 35 | I21: =12+8+5+2 -> 27 | K21: =IF(H21=I21,"完结",IF(H21>I21,"下载中")) -> 下载中 | L21: 20 | O21: =IF(H21=L21,"完",IF(H21>L21,"未")) -> 未 | V21: 万玲玲 | X21: 20-高维解读-时事点评 | Z21: 人体与灵魂的未解之谜 | AA21: 省版 | AB21: 2025/6/4 | AE21: =VLOOKUP($E21,$Z$2:$AD$76,2,FALSE) -> #N/A | AF21: =VLOOKUP($E21,$Z$2:$AD$76,3,FALSE) -> #N/A | AG21: =VLOOKUP($E21,$Z$2:$AD$76,4,FALSE) -> #N/A | AH21: =VLOOKUP($E21,$Z$2:$AD$76,5,FALSE) -> #N/A | AK21: 03-佛法知识-经典
A22: 21 | B22: 18-高维文学-小说 | C22: =YEAR(D22) -> 2020 | D22: 43892 | E22: 血河之艳 | F22: 一阶 | G22: 李静/刘小慧 | H22: 24 | I22: 24 | K22: =IF(H22=I22,"完结",IF(H22>I22,"未完结")) -> 完结 | L22: 24 | O22: =IF(H22=L22,"完",IF(H22>L22,"未")) -> 完 | V22: 李奕萱 | X22: 21-高维解读-高维影评 | Z22: 宇宙之声 | AA22: 省版 | AB22: 2025/6/4 | AC22: 2025/7/4 | AD22: 已发证 | AE22: =VLOOKUP($E22,$Z$2:$AD$76,2,FALSE) -> #N/A | AF22: =VLOOKUP($E22,$Z$2:$AD$76,3,FALSE) -> #N/A | AG22: =VLOOKUP($E22,$Z$2:$AD$76,4,FALSE) -> #N/A | AH22: =VLOOKUP($E22,$Z$2:$AD$76,5,FALSE) -> #N/A | AK22: 13-小说
A23: 22 | B23: 08-灵性成长-灵性基础 | C23: =YEAR(D23) -> 2020 | D23: 43907 | E23: 灵魂之光 | F23: 一阶 | G23: 刘小慧 | H23: 20 | I23: 20 | K23: =IF(H23=I23,"完结",IF(H23>I23,"未完结")) -> 完结 | L23: 20 | O23: =IF(H23=L23,"完",IF(H23>L23,"未")) -> 完 | P23: 省版 | Q23: 2025/6/4 | R23: 2025/7/4 | S23: 已发证 | V23: 孙晓辰 | X23: 22-高维讯息-基督世界 | Z23: 灵魂之光 | AA23: 省版 | AB23: 2025/6/4 | AC23: 2025/7/4 | AD23: 已发证 | AE23: =VLOOKUP($E23,$Z$2:$AD$76,2,FALSE) -> 省版 | AF23: =VLOOKUP($E23,$Z$2:$AD$76,3,FALSE) -> 2025/6/4 | AG23: =VLOOKUP($E23,$Z$2:$AD$76,4,FALSE) -> 2025/7/4 | AH23: =VLOOKUP($E23,$Z$2:$AD$76,5,FALSE) -> 已发证 | AK23: 08-灵性成长
A24: 23 | B24: 08-灵性成长-灵性基础 | C24: =YEAR(D24) -> 2020 | D24: 43951 | E24: 命运之门 | F24: 一阶 | G24: 刘小慧 | H24: 10 | I24: 10 | K24: =IF(H24=I24,"完结",IF(H24>I24,"未完结")) -> 完结 | L24: 10 | O24: =IF(H24=L24,"完",IF(H24>L24,"未")) -> 完 | V24: 林臻皓 | X24: 23-高维讯息-穆斯林世界 | Z24: 363号宇宙史 | AA24: 国版 | AB24: 2025/4/29 | AC24: 2025/4/30 | AD24: 已发证 | AE24: =VLOOKUP($E24,$Z$2:$AD$76,2,FALSE) -> #N/A | AF24: =VLOOKUP($E24,$Z$2:$AD$76,3,FALSE) -> #N/A | AG24: =VLOOKUP($E24,$Z$2:$AD$76,4,FALSE) -> #N/A | AH24: =VLOOKUP($E24,$Z$2:$AD$76,5,FALSE) -> #N/A | AK24: 08-灵性成长
A25: 24 | B25: 08-灵性成长-灵性基础 | C25: =YEAR(D25) -> 2020 | D25: 43966 | E25: 三生三世 | F25: 一阶 | G25: 惠敏 | H25: 9 | I25: 9 | K25: =IF(H25=I25,"完结",IF(H25>I25,"未完结")) -> 完结 | L25: 9 | O25: =IF(H25=L25,"完",IF(H25>L25,"未")) -> 完 | V25: 海榆 | X25: 24-百家讲坛 | Z25: 地球文明史 | AA25: 国版 | AB25: 2025/5/27 | AC25: 2025/5/28 | AD25: 已发证 | AE25: =VLOOKUP($E25,$Z$2:$AD$76,2,FALSE) -> #N/A | AF25: =VLOOKUP($E25,$Z$2:$AD$76,3,FALSE) -> #N/A | AG25: =VLOOKUP($E25,$Z$2:$AD$76,4,FALSE) -> #N/A | AH25: =VLOOKUP($E25,$Z$2:$AD$76,5,FALSE) -> #N/A | AK25: 08-灵性成长
A26: 25 | B26: 19-人物揭秘/传记 | C26: =YEAR(D26) -> 2020 | D26: 43979 | E26: 紫薇圣人与弥赛亚 | F26: 二阶 | G26: 徐丹 | H26: 4 | I26: 4 | K26: =IF(H26=I26,"完结",IF(H26>I26,"未完结")) -> 完结 | L26: 0 | O26: =IF(H26=L26,"完",IF(H26>L26,"未")) -> 未 | V26: 吴英 | Z26: 亚特兰蒂斯的兴衰 | AA26: 国版 | AB26: 2025/5/28 | AC26: 2025/5/28 | AD26: 已发证 | AE26: =VLOOKUP($E26,$Z$2:$AD$76,2,FALSE) -> #N/A | AF26: =VLOOKUP($E26,$Z$2:$AD$76,3,FALSE) -> #N/A | AG26: =VLOOKUP($E26,$Z$2:$AD$76,4,FALSE) -> #N/A | AH26: =VLOOKUP($E26,$Z$2:$AD$76,5,FALSE) -> #N/A | AK26: 15-人物揭秘
A27: 26 | B27: 04-地球文明/地球扬升 | C27: =YEAR(D27) -> 2020 | D27: 43983 | E27: 地球文明史 | F27: 一阶 | G27: 刘冬梅 | H27: 14 | I27: 13 | K27: =IF(H27=I27,"完结",IF(H27>I27,"下载中")) -> 下载中 | L27: 13 | O27: =IF(H27=L27,"完",IF(H27>L27,"未")) -> 未 | P27: 国版 | Q27: 2025/5/27 | R27: 2025/5/28 | S27: 已发证 | V27: 杜旻旻 | Z27: 海底之星：鲛人族 | AA27: 国版 | AB27: 2025/5/28 | AC27: 2025/5/28 | AD27: 已发证 | AE27: =VLOOKUP($E27,$Z$2:$AD$76,2,FALSE) -> 国版 | AF27: =VLOOKUP($E27,$Z$2:$AD$76,3,FALSE) -> 2025/5/27 | AG27: =VLOOKUP($E27,$Z$2:$AD$76,4,FALSE) -> 2025/5/28 | AH27: =VLOOKUP($E27,$Z$2:$AD$76,5,FALSE) -> 已发证 | AK27: 04-地球扬升
A28: 27 | B28: 02-宇宙知识-平行空间 | C28: =YEAR(D28) -> 2020 | D28: 43987 | E28: 火星智慧 | F28: 一阶 | G28: 惠敏 | H28: 10 | I28: 10 | K28: =IF(H28=I28,"完结",IF(H28>I28,"未完结")) -> 完结 | L28: 10 | O28: =IF(H28=L28,"完",IF(H28>L28,"未")) -> 完 | P28: 国版 | Q28: 2025/5/28 | R28: 2025/5/28 | S28: 已发证 | V28: 陈琪琪/刘小慧 | Z28: 363号宇宙科学家之三次元释义 | AA28: 省版 | AB28: 2025/6/2 | AC28: 2025/7/3 | AD28: 已发证 | AE28: =VLOOKUP($E28,$Z$2:$AD$76,2,FALSE) -> 国版 | AF28: =VLOOKUP($E28,$Z$2:$AD$76,3,FALSE) -> 2025/5/28 | AG28: =VLOOKUP($E28,$Z$2:$AD$76,4,FALSE) -> 2025/5/28 | AH28: =VLOOKUP($E28,$Z$2:$AD$76,5,FALSE) -> 已发证 | AK28: 07-宇宙知识-宇宙文明
A29: 28 | B29: 02-宇宙知识-平行空间 | C29: =YEAR(D29) -> 2020 | D29: 43998 | E29: 龙族的文明 | F29: 一阶 | G29: 张轶群 | H29: 11 | I29: 11 | K29: =IF(H29=I29,"完结",IF(H29>I29,"未完结")) -> 完结 | L29: 3 | O29: =IF(H29=L29,"完",IF(H29>L29,"未")) -> 未 | P29: 国版 | Q29: 2025/5/5 | R29: 2025/5/5 | S29: 已发证 | V29: 李静/刘小慧 | Z29: 宇宙大百科 | AB29: 2025/6/6 | AD29: 阶段稿已存证 | AE29: =VLOOKUP($E29,$Z$2:$AD$76,2,FALSE) -> 国版 | AF29: =VLOOKUP($E29,$Z$2:$AD$76,3,FALSE) -> 2025/5/5 | AG29: =VLOOKUP($E29,$Z$2:$AD$76,4,FALSE) -> 2025/5/5 | AH29: =VLOOKUP($E29,$Z$2:$AD$76,5,FALSE) -> 已发证 | AK29: 07-宇宙知识-宇宙文明
A30: 29 | B30: 02-宇宙知识-平行空间 | C30: =YEAR(D30) -> 2020 | D30: 44008 | E30: 龙族的画报 | F30: 一阶 | G30: 张轶群 | H30: 2 | I30: 2 | K30: =IF(H30=I30,"完结",IF(H30>I30,"未完结")) -> 完结 | L30: 0 | O30: =IF(H30=L30,"完",IF(H30>L30,"未")) -> 未 | V30: 卢卢 | Z30: 363号宇宙空间构成学 | AA30: 省版 | AB30: 2025/6/2 | AC30: 2025/7/3 | AD30: 已发证 | AE30: =VLOOKUP($E30,$Z$2:$AD$76,2,FALSE) -> #N/A | AF30: =VLOOKUP($E30,$Z$2:$AD$76,3,FALSE) -> #N/A | AG30: =VLOOKUP($E30,$Z$2:$AD$76,4,FALSE) -> #N/A | AH30: =VLOOKUP($E30,$Z$2:$AD$76,5,FALSE) -> #N/A | AK30: 07-宇宙知识-宇宙文明
A31: 30 | B31: 12-修行修心-实修指南 | C31: =YEAR(D31) -> 2020 | D31: 44015 | E31: 禅修的秘密 | F31: 二阶 | G31: 惠敏 | H31: 16 | I31: 16 | K31: =IF(H31=I31,"完结",IF(H31>I31,"未完结")) -> 完结 | L31: 16 | O31: =IF(H31=L31,"完",IF(H31>L31,"未")) -> 完 | V31: 冯昆 | Z31: 363号宇宙星系运算法则 | AA31: 省版 | AB31: 2025/6/2 | AC31: 2025/7/3 | AD31: 已发证 | AE31: =VLOOKUP($E31,$Z$2:$AD$76,2,FALSE) -> #N/A | AF31: =VLOOKUP($E31,$Z$2:$AD$76,3,FALSE) -> #N/A | AG31: =VLOOKUP($E31,$Z$2:$AD$76,4,FALSE) -> #N/A | AH31: =VLOOKUP($E31,$Z$2:$AD$76,5,FALSE) -> #N/A | AK31: 05-禅修指导
A32: 31 | B32: 02-宇宙知识-平行空间 | C32: =YEAR(D32) -> 2020 | D32: 44021 | E32: 龙的秘密 | F32: 一阶 | G32: 张轶群 | H32: 12 | I32: 12 | K32: =IF(H32=I32,"完结",IF(H32>I32,"未完结")) -> 完结 | L32: 0 | O32: =IF(H32=L32,"完",IF(H32>L32,"未")) -> 未 | V32: 夏柚佳 | Z32: 363号宇宙银河系的构成 | AA32: 省版 | AB32: 2025/6/2 | AC32: 2025/7/3 | AD32: 已发证 | AE32: =VLOOKUP($E32,$Z$2:$AD$76,2,FALSE) -> #N/A | AF32: =VLOOKUP($E32,$Z$2:$AD$76,3,FALSE) -> #N/A | AG32: =VLOOKUP($E32,$Z$2:$AD$76,4,FALSE) -> #N/A | AH32: =VLOOKUP($E32,$Z$2:$AD$76,5,FALSE) -> #N/A | AK32: 07-宇宙知识-宇宙文明
A33: 32 | B33: 02-宇宙知识-平行空间 | C33: =YEAR(D33) -> 2020 | D33: 44023 | E33: 金星世界 | F33: 一阶 | G33: 惠敏 | H33: 5 | I33: 5 | K33: =IF(H33=I33,"完结",IF(H33>I33,"未完结")) -> 完结 | L33: 4 | O33: =IF(H33=L33,"完",IF(H33>L33,"未")) -> 未 | P33: 国版 | Q33: 2025/5/28 | R33: 2025/5/28 | S33: 已发证 | Z33: 遨游宇宙 | AA33: 省版 | AB33: 2025/6/2 | AC33: 2025/7/4 | AD33: 已发证 | AE33: =VLOOKUP($E33,$Z$2:$AD$76,2,FALSE) -> 国版 | AF33: =VLOOKUP($E33,$Z$2:$AD$76,3,FALSE) -> 2025/5/28 | AG33: =VLOOKUP($E33,$Z$2:$AD$76,4,FALSE) -> 2025/5/28 | AH33: =VLOOKUP($E33,$Z$2:$AD$76,5,FALSE) -> 已发证 | AK33: 07-宇宙知识-宇宙文明
A34: 33 | B34: 02-宇宙知识-平行空间 | C34: =YEAR(D34) -> 2020 | D34: 44028 | E34: 龙族如何管理三次元地球 | F34: 一阶 | G34: 张轶群 | H34: 4 | I34: 4 | K34: 无文稿 | L34: 0 | O34: =IF(H34=L34,"完",IF(H34>L34,"未")) -> 未 | Z34: 万有空间论 | AA34: 省版 | AB34: 2025/6/3 | AC34: 2025/7/4 | AD34: 已发证 | AE34: =VLOOKUP($E34,$Z$2:$AD$76,2,FALSE) -> #N/A | AF34: =VLOOKUP($E34,$Z$2:$AD$76,3,FALSE) -> #N/A | AG34: =VLOOKUP($E34,$Z$2:$AD$76,4,FALSE) -> #N/A | AH34: =VLOOKUP($E34,$Z$2:$AD$76,5,FALSE) -> #N/A | AK34: 07-宇宙知识-宇宙文明
A35: 34 | B35: 12-修行修心-实修指南 | C35: =YEAR(D35) -> 2020 | D35: 44031 | E35: 解密灵魂出窍 | F35: 一阶 | G35: 张轶群 | H35: 5 | I35: 5 | K35: =IF(H35=I35,"完结",IF(H35>I35,"未完结")) -> 完结 | L35: 5 | O35: =IF(H35=L35,"完",IF(H35>L35,"未")) -> 完 | P35: 省版 | Q35: 2025/6/5 | R35: 0 | S35: 0 | Z35: 日光宇宙 | AA35: 省版 | AB35: 2025/6/4 | AC35: 2025/7/4 | AD35: 已发证 | AE35: =VLOOKUP($E35,$Z$2:$AD$76,2,FALSE) -> 省版 | AF35: =VLOOKUP($E35,$Z$2:$AD$76,3,FALSE) -> 2025/6/5 | AG35: =VLOOKUP($E35,$Z$2:$AD$76,4,FALSE) -> 0 | AH35: =VLOOKUP($E35,$Z$2:$AD$76,5,FALSE) -> 0 | AK35: 05-禅修指导
A36: 35 | B36: 12-修行修心-实修指南 | C36: =YEAR(D36) -> 2020 | D36: 44031 | E36: 天目 | F36: 一阶 | G36: 惠敏 | H36: 6 | I36: 6 | K36: =IF(H36=I36,"完结",IF(H36>I36,"未完结")) -> 完结 | L36: 4 | O36: =IF(H36=L36,"完",IF(H36>L36,"未")) -> 未 | Z36: 天河水，神圣的母亲河 | AA36: 省版 | AB36: 2025/6/4 | AC36: 2025/7/4 | AD36: 已发证 | AE36: =VLOOKUP($E36,$Z$2:$AD$76,2,FALSE) -> #N/A | AF36: =VLOOKUP($E36,$Z$2:$AD$76,3,FALSE) -> #N/A | AG36: =VLOOKUP($E36,$Z$2:$AD$76,4,FALSE) -> #N/A | AH36: =VLOOKUP($E36,$Z$2:$AD$76,5,FALSE) -> #N/A | AK36: 05-禅修指导
A37: 36 | B37: 12-修行修心-实修指南 | C37: =YEAR(D37) -> 2020 | D37: 44031 | E37: 中脉开启方法 | F37: 三阶 | G37: 刘小慧 | H37: 7 | I37: 7 | K37: =IF(H37=I37,"完结",IF(H37>I37,"未完结")) -> 完结 | L37: 7 | O37: =IF(H37=L37,"完",IF(H37>L37,"未")) -> 完 | Z37: 363号宇宙科学系列（暗物质+反物质+引力波） | AA37: 省版 | AB37: 2025/5/31 | AC37: 2025/7/3 | AD37: 已发证 | AE37: =VLOOKUP($E37,$Z$2:$AD$76,2,FALSE) -> #N/A | AF37: =VLOOKUP($E37,$Z$2:$AD$76,3,FALSE) -> #N/A | AG37: =VLOOKUP($E37,$Z$2:$AD$76,4,FALSE) -> #N/A | AH37: =VLOOKUP($E37,$Z$2:$AD$76,5,FALSE) -> #N/A | AK37: 05-禅修指导
A38: 37 | B38: 08-灵性成长-灵性基础 | C38: =YEAR(D38) -> 2020 | D38: 44036 | E38: 倾听花开的声音 | F38: - | G38: 张轶群 | H38: 6 | I38: 2 | K38: 暂停 | L38: 0 | O38: =IF(H38=L38,"完",IF(H38>L38,"未")) -> 未 | Z38: 暗物质，宇宙的卸载器 | AA38: 省版 | AB38: 2025/5/31 | AC38: 2025/7/3 | AD38: 已发证 | AE38: =VLOOKUP($E38,$Z$2:$AD$76,2,FALSE) -> #N/A | AF38: =VLOOKUP($E38,$Z$2:$AD$76,3,FALSE) -> #N/A | AG38: =VLOOKUP($E38,$Z$2:$AD$76,4,FALSE) -> #N/A | AH38: =VLOOKUP($E38,$Z$2:$AD$76,5,FALSE) -> #N/A | AK38: 99-暂停
A39: 38 | B39: 12-修行修心-实修指南 | C39: =YEAR(D39) -> 2020 | D39: 44038 | E39: 灵魂觉醒 | F39: 一阶 | G39: 张轶群 | H39: 6 | I39: 6 | K39: =IF(H39=I39,"完结",IF(H39>I39,"未完结")) -> 完结 | L39: 6 | O39: =IF(H39=L39,"完",IF(H39>L39,"未")) -> 完 | P39: 省版 | Q39: 2025/6/5 | R39: 0 | S39: 0 | Z39: 时光机穿越 | AA39: 省版 | AB39: 2025/5/31 | AC39: 2025/7/3 | AD39: 已发证 | AE39: =VLOOKUP($E39,$Z$2:$AD$76,2,FALSE) -> 省版 | AF39: =VLOOKUP($E39,$Z$2:$AD$76,3,FALSE) -> 2025/6/5 | AG39: =VLOOKUP($E39,$Z$2:$AD$76,4,FALSE) -> 0 | AH39: =VLOOKUP($E39,$Z$2:$AD$76,5,FALSE) -> 0 | AK39: 05-禅修指导
A40: 39 | B40: 04-地球文明/地球扬升 | C40: =YEAR(D40) -> 2020 | D40: 44042 | E40: 三次元地球的提升 | F40: 二阶 | G40: 刘小慧 | H40: 5 | I40: 5 | K40: =IF(H40=I40,"完结",IF(H40>I40,"未完结")) -> 完结 | L40: 5 | O40: =IF(H40=L40,"完",IF(H40>L40,"未")) -> 完 | P40: 省版 | Q40: 2025/5/30 | R40: 2025/7/3 | S40: 已发证 | Z40: 时间之窗 | AA40: 省版 | AB40: 2025/5/31 | AC40: 2025/7/3 | AD40: 已发证 | AE40: =VLOOKUP($E40,$Z$2:$AD$76,2,FALSE) -> 省版 | AF40: =VLOOKUP($E40,$Z$2:$AD$76,3,FALSE) -> 2025/5/30 | AG40: =VLOOKUP($E40,$Z$2:$AD$76,4,FALSE) -> 2025/7/3 | AH40: =VLOOKUP($E40,$Z$2:$AD$76,5,FALSE) -> 已发证 | AK40: 04-地球扬升
...

Sheet Sheet1
A1: 书名 | C1: 灵性成长类、佛法类、宇宙真相、地球真相揭秘类、经典类、科技类、宇宙科学类
A2: 一个灵魂飞到宇宙中的女人
A3: 经典新解
A4: 宇宙之声 | B4: 宇宙真相
A5: 宝生佛的自然课堂
A6: 外星高科技 | B6: 宇宙科学类
A7: 心法 | B7: 灵性成长类
A8: 地球提升之路
A9: 梅集
A10: 人体与灵魂的未解之谜 | B10: 灵性成长类
A11: 来自地心的问候
A12: 我眼中的宇宙之王
A13: 明日之歌
A14: 礼记
A15: 公约社区
A16: 无限
A17: 疫情报告
A18: 灵性文章合集（中英文）
A19: 森林之子
A20: 生命之花
A21: 四书五经
A22: 血河之艳
... A26: 紫薇圣人与弥赛亚
A27: 地球文明史 | B27: 地球真相揭秘类
A28: 火星智慧 | B28: 宇宙科学类
A29: 龙族的文明 | B29: 宇宙真相
A30: 龙族的画报
A31: 禅修的秘密
A32: 龙的秘密
A33: 金星世界 | B33: 宇宙真相
A34: 龙族如何管理三次元地球
A35: 解密灵魂出窍
A36: 天目 | B36: 灵性成长类
A37: 中脉开启方法
A38: 倾听花开的声音 | B38: 灵性成长类
A39: 灵魂觉醒 | B39: 灵性成长类
A40: 三次元地球的提升 | B40: 地球真相揭秘类
A41: 凤凰族的文明
A42: 四次元地球 | B42: 地球真相揭秘类
A43: 第三世界
...

Sheet 目录
A1: 宇宙藏书阁 · 统计总览
A3: 编号 | B3: 下载管道 | C3: 书目 | D3: 工作状态 | F3: 书籍分类 | G3: 书目 | I3: 年份 | J3: 书目
A4: 合计 | B4: 合计 | C4: =SUM(C5:C34) -> 368 | F4: 合计 | G4: =SUM(G5:G34) -> 368 | I4: 合计 | J4: =SUM(J5:J34) -> 368
A5: 1 | B5: 沛生 | C5: =COUNTIF(中文书目!G$2:G$1000,目录!B5) -> 60 | D5: 暂停 | F5: 01-宇宙知识-宇宙法则 | G5: =COUNTIF(中文书目!B$2:B$1000,目录!F5) -> 27 | I5: 2019 | J5: =COUNTIF(中文书目!C$2:C$1000,目录!I5) -> 9
A6: 2 | B6: 孟昭宇 | C6: =COUNTIF(中文书目!G$2:G$1000,目录!B6) -> 47 | D6: 工作中 | F6: 02-宇宙知识-平行空间 | G6: =COUNTIF(中文书目!B$2:B$1000,目录!F6) -> 30 | I6: 2020 | J6: =COUNTIF(中文书目!C$2:C$1000,目录!I6) -> 95
A7: 3 | B7: 王靖 | C7: =COUNTIF(中文书目!G$2:G$1000,目录!B7) -> 42 | D7: 暂停 | F7: 03-宇宙知识-外星文明 | G7: =COUNTIF(中文书目!B$2:B$1000,目录!F7) -> 7 | I7: 2021 | J7: =COUNTIF(中文书目!C$2:C$1000,目录!I7) -> 57
A8: 4 | B8: 惠敏 | C8: =COUNTIF(中文书目!G$2:G$1000,目录!B8) -> 27 | D8: 暂停 | F8: 04-地球文明/地球扬升 | G8: =COUNTIF(中文书目!B$2:B$1000,目录!F8) -> 17 | I8: 2022 | J8: =COUNTIF(中文书目!C$2:C$1000,目录!I8) -> 41
A9: 5 | B9: 蒋迎迎 | C9: =COUNTIF(中文书目!G$2:G$1000,目录!B9) -> 25 | D9: 暂停 | F9: 05-宇宙科学/现代科技 | G9: =COUNTIF(中文书目!B$2:B$1000,目录!F9) -> 19 | I9: 2023 | J9: =COUNTIF(中文书目!C$2:C$1000,目录!I9) -> 63
A10: 6 | B10: 蒋迎迎 | C10: =COUNTIF(中文书目!G$2:G$1000,目录!B10) -> 25 | D10: 暂停 | F10: 06-佛法基础常识 | G10: =COUNTIF(中文书目!B$2:B$1000,目录!F10) -> 10 | I10: 2024 | J10: =COUNTIF(中文书目!C$2:C$1000,目录!I10) -> 29
A11: 7 | B11: 李静 | C11: =COUNTIF(中文书目!G$2:G$1000,目录!B11) -> 17 | D11: 退转 | F11: 07-经典经文 | G11: =COUNTIF(中文书目!B$2:B$1000,目录!F11) -> 18 | I11: 2025 | J11: =COUNTIF(中文书目!C$2:C$1000,目录!I11) -> 74
A12: 8 | B12: 张轶群 | C12: =COUNTIF(中文书目!G$2:G$1000,目录!B12) -> 10 | D12: 暂停 | F12: 08-灵性成长-灵性基础 | G12: =COUNTIF(中文书目!B$2:B$1000,目录!F12) -> 55
A13: 9 | B13: 刘冬梅 | C13: =COUNTIF(中文书目!G$2:G$1000,目录!B13) -> 8 | D13: 暂停 | F13: 10-灵性成长-身心疗愈 | G13: =COUNTIF(中文书目!B$2:B$1000,目录!F13) -> 31
A14: 10 | B14: 陈琪琪 | C14: =COUNTIF(中文书目!G$2:G$1000,目录!B14) -> 7 | D14: 暂停 | F14: 11-修行修心-修心基础 | G14: =COUNTIF(中文书目!B$2:B$1000,目录!F14) -> 22
A15: 11 | B15: 林巧玲 | C15: =COUNTIF(中文书目!G$2:G$1000,目录!B15) -> 57 | D15: 工作中 | F15: 12-修行修心-实修指南 | G15: =COUNTIF(中文书目!B$2:B$1000,目录!F15) -> 25
A16: 12 | B16: 周统志 | C16: =COUNTIF(中文书目!G$2:G$1000,目录!B16) -> 5 | D16: 退转 | F16: 13-落地智慧-日常生活 | G16: =COUNTIF(中文书目!B$2:B$1000,目录!F16) -> 11
A17: 13 | B17: 昱嘉 | C17: =COUNTIF(中文书目!G$2:G$1000,目录!B17) -> 5 | D17: 暂停 | F17: 14-落地智慧-事业财富 | G17: =COUNTIF(中文书目!B$2:B$1000,目录!F17) -> 11
A18: 14 | B18: 温愉琦 | C18: =COUNTIF(中文书目!G$2:G$1000,目录!B18) -> 4 | D18: 暂停 | F18: 15-落地智慧-人际关系 | G18: =COUNTIF(中文书目!B$2:B$1000,目录!F18) -> 18
A19: 15 | B19: 共同参与 | C19: =COUNTIF(中文书目!G$2:G$1000,目录!B19) -> 5 | D19: - | F19: 16-新文明新商业 | G19: =COUNTIF(中文书目!B$2:B$1000,目录!F19) -> 8
A20: 16 | B20: 徐丹 | C20: =COUNTIF(中文书目!G$2:G$1000,目录!B20) -> 2 | D20: 暂停 | F20: 17-高维文学-散文诗 | G20: =COUNTIF(中文书目!B$2:B$1000,目录!F20) -> 2
A21: 17 | B21: 含灵 | C21: =COUNTIF(中文书目!G$2:G$1000,目录!B21) -> 2 | D21: 工作中 | F21: 18-高维文学-小说 | G21: =COUNTIF(中文书目!B$2:B$1000,目录!F21) -> 13
A22: 18 | B22: 星姐 | C22: =COUNTIF(中文书目!G$2:G$1000,目录!B22) -> 2 | D22: 暂停 | F22: 19-人物揭秘/传记 | G22: =COUNTIF(中文书目!B$2:B$1000,目录!F22) -> 15
A23: 19 | B23: 万玲玲 | C23: =COUNTIF(中文书目!G$2:G$1000,目录!B23) -> 2 | D23: 暂停 | F23: 20-高维解读-时事点评 | G23: =COUNTIF(中文书目!B$2:B$1000,目录!F23) -> 1
... A27: 23 | B27: 海榆 | C27: =COUNTIF(中文书目!G$2:G$1000,目录!B27) -> 1 | D27: 暂停 | F27: 24-百家讲坛 | G27: =COUNTIF(中文书目!B$2:B$1000,目录!F27) -> 11
A28: 24 | B28: 吴英 | C28: =COUNTIF(中文书目!G$2:G$1000,目录!B28) -> 1 | D28: 暂停 | F28: 99-暂停 | G28: {=COUNTIF(中文书目!K$2:K$1000,暂停)} -> 0
A29: 25 | B29: 杜旻旻 | C29: =COUNTIF(中文书目!G$2:G$1000,目录!B29) -> 1 | D29: 暂停
A30: 26 | B30: 陈琪琪/刘小慧 | C30: =COUNTIF(中文书目!G$2:G$1000,目录!B30) -> 0 | D30: 暂停
A31: 27 | B31: 李静/刘小慧 | C31: =COUNTIF(中文书目!G$2:G$1000,目录!B31) -> 1 | D31: 暂停
A32: 28 | B32: 卢卢 | C32: =COUNTIF(中文书目!G$2:G$1000,目录!B32) -> 1 | D32: 暂停
A33: 29 | B33: 冯昆 | C33: =COUNTIF(中文书目!G$2:G$1000,目录!B33) -> 1 | D33: 暂停
A34: 30 | B34: 夏柚佳 | C34: =COUNTIF(中文书目!G$2:G$1000,目录!B34) -> 4 | D34: 工作中

Sheet 翻译对照表
A1: 序号 | B1: 中文书名 | C1: 总章节数 | D1: 下载数 | E1: 英文书名 | F1: 总章节数 | G1: 下载数
A2: 1 | B2: 一个灵魂飞到宇宙中的女人 | C2: 2 | D2: 2
A3: 2 | B3: 经典新解 | C3: 5 | D3: 5
A4: 3 | B4: 宇宙之声 | C4: 19 | D4: 19
A5: 4 | B5: 宝生佛的自然课堂 | C5: 27 | D5: 27
A6: 5 | B6: 外星高科技 | C6: 5 | D6: 5
A7: 6 | B7: 心法 | C7: 19 | D7: 19
A8: 7 | B8: 地球提升之路 | C8: 8 | D8: 8
A9: 8 | B9: 梅集 | C9: 145 | D9: 145
A10: 9 | B10: 人体与灵魂的未解之谜 | C10: 16 | D10: 16
A11: 10 | B11: 来自地心的问候 | C11: 19 | D11: 19
A12: 11 | B12: 我眼中的宇宙之王 | C12: 16 | D12: 16
A13: 12 | B13: 明日之歌 | C13: 19 | D13: 19
A14: 13 | B14: 礼记 | C14: 8 | D14: 8
A15: 14 | B15: 公约社区 | C15: ？ | D15: 19
A16: 15 | B16: 无限 | C16: 4 | D16: 4
A17: 16 | B17: 疫情报告 | C17: 1 | D17: 1
A18: 17 | B18: 灵性文章合集（中英文） | C18: 27 | D18: 27
A19: 18 | B19: 森林之子 | C19: 10 | D19: 10
A20: 19 | B20: 生命之花 | C20: 10 | D20: 10
A21: 20 | B21: 四书五经 | C21: =12+8+5+2+8 -> 35 | D21: =12+8+5+2 -> 27
A22: 21 | B22: 血河之艳 | C22: 24 | D22: 24
A23: 22 | B23: 灵魂之光 | C23: 20 | D23: 20
A24: 23 | B24: 命运之门 | C24: 10 | D24: 10
A25: 24 | B25: 三生三世 | C25: 9 | D25: 9
A26: 25 | B26: 紫薇圣人与弥赛亚 | C26: 4 | D26: 4
A27: 26 | B27: 地球文明史 | C27: 14 | D27: 13
A28: 27 | B28: 火星智慧 | C28: 10 | D28: 10
A29: 28 | B29: 龙族的文明 | C29: 11 | D29: 11
A30: 29 | B30: 龙族的画报 | C30: 2 | D30: 2
A31: 30 | B31: 禅修的秘密 | C31: 16 | D31: 16
A32: 31 | B32: 龙的秘密 | C32: 12 | D32: 12
A33: 32 | B33: 金星世界 | C33: 5 | D33: 5
... A82: 81 | B82: 链接灵魂 | C82: 6 | D82: 6
A83: 82 | B83: 弥赛亚 | C83: 36
A84: 83 | B84: 天使之翼 | C84: 7 | D84: 7
A85: 84 | B85: 扬升如约而至 | C85: 1 | D85: 1
A86: 85 | B86: 基督意识 | C86: 12 | D86: 7
A87: 86 | B87: 无极老母传记 | C87: 6 | D87: 5
A88: 87 | B88: 极致大脑 | C88: 5 | D88: 5
...

Sheet 英文书目
A1: 序号 | B1: 标签 | C1: 首篇时间 | D1: 书名 | E1: 阶别 | F1: 管道 | G1: 总章节数 | H1: 下载数 | I1: 下载状态 | J1: 版权类别 | K1: 存证日期 | L1: 版权登记日期 | M1: 版权状态 | P1: 管道 | Q1: 阶别
